Workbook

Sheet Indice
A1: RetailCo · Capacidad de almacenamiento en temporada alta
A2: Datos sintéticos generados para un proyecto de portafolio. No corresponden a ninguna empresa.
A4: Hoja | B4: Contenido
A5: Parametros | B5: Parámetros calibrados por centro (a, b), posiciones, ocupación inicial, capacidad de alistamiento y supuestos editables
A6: Forecast | B6: Forecast de octubre: cajas y piezas por centro y semana, S43 2025 – S13 2026
A7: Proyeccion | B7: Ocupación semanal proyectada con el modelo de flujo, posiciones faltantes y ocupación de la red
A8: Semaforo | B8: Pico, semana pico, semanas sobre 100 %, posiciones faltantes, cubrimiento y estado por centro
A9: Historico | B9: Histórico limpio por centro y semana (salida del notebook)
A10: Cumplimiento | B10: Real ÷ forecast de recibo y alistamiento por centro y periodo
A11: Backtest | B11: Error del método a 11 semanas frente a 'sin cambio' y al atajo de 33 cajas (resultado del notebook)
A14: Convenciones
A15: Texto azul: dato de entrada
A16: Texto negro: fórmula
A17: Texto verde: vínculo a otra hoja
A18: Fondo amarillo: supuesto editable
A20: Cómo usarlo: cambia el recibo adicional en la rampa (Parametros!C4) a 5 % o 10 % y revisa el Semaforo.

Sheet Parametros
A1: Parámetros del modelo
A3: Supuestos editables
B4: Recibo adicional en la rampa S43–S51 (escenario base) | C4: 0 | D4: Sensibilidad: % de recibo sobre el forecast en S43–S51. Notebook: 0 %, 5 % y 10 %.
B5: Umbral crítico de ocupación | C5: 1 | D5: Pico sobre este valor con el forecast = Crítico
B6: Recibo adicional del escenario de alerta | C6: 0.1 | D6: Alerta: el pico supera el umbral solo con este % extra de recibo en S43–S51
B7: Cajas por ubicación del atajo | C7: 33 | D7: Supuesto del método simplificado (descartado en el backtest)
A9: Centro | B9: Tipo | C9: Posiciones | D9: a (pp/caja) | E9: b (pp/pieza) | F9: Ocupación S42 2025 | G9: Piezas por caja (a/b) | H9: Cajas por posición | I9: Capacidad alistamiento (piezas/sem) | J9: Piezas por bulto
A10: CD-Norte | B10: Propio | C10: 4800 | D10: 0.0003575469 | E10: 4.215479e-05 | F10: 0.8019 | G10: =D10/E10 -> 8.4817621 | H10: =100/(D10*C10) -> 58.267414 | I10: 580000 | J10: 9.6
A11: CD-Centro | B11: Propio | C11: 1900 | D11: 0.0010955244 | E11: 0.00014107068 | F11: 0.7078 | G11: =D11/E11 -> 7.7657834 | H11: =100/(D11*C11) -> 48.042363 | I11: 165000 | J11: 8.4
A12: CD-Oriente | B12: Propio | C12: 1300 | D12: 0.001636805 | E12: 0.0002293065 | F12: 0.6875 | G12: =D12/E12 -> 7.1380662 | H12: =100/(D12*C12) -> 46.995871 | I12: 105000 | J12: 8.6
A13: CD-Bebidas | B13: Propio | C13: 1500 | D13: 0.00070068859 | E13: 0.000268789 | F13: 0.7092 | G13: =D13/E13 -> 2.6068351 | H13: =100/(D13*C13) -> 95.144502 | I13: 50000 | J13: 2.8
A14: OPL-Frio | B14: OPL | C14: 350 | D14: 0.0052146806 | E14: 0.00082396796 | F14: 0.6306 | G14: =D14/E14 -> 6.328742 | H14: =100/(D14*C14) -> 54.790371 | I14: 21000 | J14: 7
A16: a y b se calibraron en el notebook (sección 4). La ocupación inicial es la real de la S42 de 2025.

Sheet Forecast
A1: Forecast de temporada (versión octubre)
A3: Año | B3: Semana | C3: Rampa (1 = S43–S51) | D3: CD-Norte cajas | E3: CD-Norte piezas | F3: CD-Centro cajas | G3: CD-Centro piezas | H3: CD-Oriente cajas | I3: CD-Oriente piezas | J3: CD-Bebidas cajas | K3: CD-Bebidas piezas | L3: OPL-Frio cajas | M3: OPL-Frio piezas
A4: 2025 | B4: 43 | C4: =IF(AND(A4=2025,B4>=43,B4<=51),1,0) -> 1 | D4: 46864 | E4: 450534 | F4: 14475 | G4: 126783 | H4: 9491 | I4: 86320 | J4: 14454 | K4: 41000 | L4: 2596 | M4: 17543
A5: 2025 | B5: 44 | C5: =IF(AND(A5=2025,B5>=43,B5<=51),1,0) -> 1 | D5: 47697 | E5: 447719 | F5: 15642 | G5: 137229 | H5: 10408 | I5: 87499 | J5: 18890 | K5: 40050 | L5: 2521 | M5: 17995
A6: 2025 | B6: 45 | C6: =IF(AND(A6=2025,B6>=43,B6<=51),1,0) -> 1 | D6: 51695 | E6: 444345 | F6: 15760 | G6: 139498 | H6: 10132 | I6: 84219 | J6: 21691 | K6: 41796 | L6: 2949 | M6: 18893
A7: 2025 | B7: 46 | C7: =IF(AND(A7=2025,B7>=43,B7<=51),1,0) -> 1 | D7: 67133 | E7: 452671 | F7: 20561 | G7: 133593 | H7: 11040 | I7: 83153 | J7: 23171 | K7: 41936 | L7: 3442 | M7: 18121
A8: 2025 | B8: 47 | C8: =IF(AND(A8=2025,B8>=43,B8<=51),1,0) -> 1 | D8: 69097 | E8: 441961 | F8: 21706 | G8: 139373 | H8: 12765 | I8: 89425 | J8: 22066 | K8: 43885 | L8: 4778 | M8: 18600
A9: 2025 | B9: 48 | C9: =IF(AND(A9=2025,B9>=43,B9<=51),1,0) -> 1 | D9: 76972 | E9: 446212 | F9: 23935 | G9: 131252 | H9: 14025 | I9: 82790 | J9: 21161 | K9: 48527 | L9: 4899 | M9: 20137
A10: 2025 | B10: 49 | C10: =IF(AND(A10=2025,B10>=43,B10<=51),1,0) -> 1 | D10: 70086 | E10: 468406 | F10: 25121 | G10: 158880 | H10: 14177 | I10: 86763 | J10: 16480 | K10: 46578 | L10: 4305 | M10: 19312
A11: 2025 | B11: 50 | C11: =IF(AND(A11=2025,B11>=43,B11<=51),1,0) -> 1 | D11: 73165 | E11: 479841 | F11: 22034 | G11: 149803 | H11: 15201 | I11: 97714 | J11: 15388 | K11: 45636 | L11: 4258 | M11: 19786
A12: 2025 | B12: 51 | C12: =IF(AND(A12=2025,B12>=43,B12<=51),1,0) -> 1 | D12: 70172 | E12: 523470 | F12: 18027 | G12: 142613 | H12: 13536 | I12: 92754 | J12: 11600 | K12: 44247 | L12: 3270 | M12: 20516
A13: 2025 | B13: 52 | C13: =IF(AND(A13=2025,B13>=43,B13<=51),1,0) -> 0 | D13: 52505 | E13: 495635 | F13: 16540 | G13: 142578 | H13: 12768 | I13: 93245 | J13: 8456 | K13: 41640 | L13: 2560 | M13: 20823
A14: 2026 | B14: 1 | C14: =IF(AND(A14=2025,B14>=43,B14<=51),1,0) -> 0 | D14: 39874 | E14: 467759 | F14: 13630 | G14: 138981 | H14: 9617 | I14: 81782 | J14: 8658 | K14: 42417 | L14: 1932 | M14: 18635
A15: 2026 | B15: 2 | C15: =IF(AND(A15=2025,B15>=43,B15<=51),1,0) -> 0 | D15: 27753 | E15: 438678 | F15: 13788 | G15: 145790 | H15: 8723 | I15: 82852 | J15: 8763 | K15: 39464 | L15: 1390 | M15: 18268
... A26: 2026 | B26: 13 | C26: =IF(AND(A26=2025,B26>=43,B26<=51),1,0) -> 0 | D26: 50625 | E26: 436038 | F26: 19165 | G26: 149379 | H26: 13447 | I26: 91798 | J26: 16494 | K26: 44635 | L26: 3171 | M26: 20807

Sheet Proyeccion
A1: Ocupación proyectada (modelo de flujo)
A2: ocup(t) = ocup(t−1) + a × cajas(t) × (1 + recibo adicional × rampa) − b × piezas(t), en puntos porcentuales
A4: Año | B4: Semana | C4: CD-Norte ocupación | D4: CD-Centro ocupación | E4: CD-Oriente ocupación | F4: CD-Bebidas ocupación | G4: OPL-Frio ocupación | H4: CD-Norte faltantes | I4: CD-Centro faltantes | J4: CD-Oriente faltantes | K4: CD-Bebidas faltantes | L4: OPL-Frio faltantes | M4: Red propia (ponderada) | N4: CD-Norte ocupación escenario alerta | O4: CD-Centro ocupación escenario alerta | P4: CD-Oriente ocupación escenario alerta | Q4: CD-Bebidas ocupación escenario alerta | R4: OPL-Frio ocupación escenario alerta
A5: Inicio | B5: S42 | C5: =Parametros!F10 -> 0.8019 | D5: =Parametros!F11 -> 0.7078 | E5: =Parametros!F12 -> 0.6875 | F5: =Parametros!F13 -> 0.7092 | G5: =Parametros!F14 -> 0.6306 | N5: =Parametros!F10 -> 0.8019 | O5: =Parametros!F11 -> 0.7078 | P5: =Parametros!F12 -> 0.6875 | Q5: =Parametros!F13 -> 0.7092 | R5: =Parametros!F14 -> 0.6306
A6: =Forecast!A4 -> 2025 | B6: =Forecast!B4 -> 43 | C6: =C5+(Parametros!$D$10*Forecast!D4*(1+Parametros!$C$4*Forecast!$C4)-Parametros!$E$10*Forecast!E4)/100 -> 0.77953912 | D6: =D5+(Parametros!$D$11*Forecast!F4*(1+Parametros!$C$4*Forecast!$C4)-Parametros!$E$11*Forecast!G4)/100 -> 0.68752351 | E6: =E5+(Parametros!$D$12*Forecast!H4*(1+Parametros!$C$4*Forecast!$C4)-Parametros!$E$12*Forecast!I4)/100 -> 0.64491179 | F6: =F5+(Parametros!$D$13*Forecast!J4*(1+Parametros!$C$4*Forecast!$C4)-Parametros!$E$13*Forecast!K4)/100 -> 0.70027404 | G6: =G5+(Parametros!$D$14*Forecast!L4*(1+Parametros!$C$4*Forecast!$C4)-Parametros!$E$14*Forecast!M4)/100 -> 0.62142441 | H6: =MAX(0,C6-1)*Parametros!$C$10 -> 0 | I6: =MAX(0,D6-1)*Parametros!$C$11 -> 0 | J6: =MAX(0,E6-1)*Parametros!$C$12 -> 0 | K6: =MAX(0,F6-1)*Parametros!$C$13 -> 0 | L6: =MAX(0,G6-1)*Parametros!$C$14 -> 0 | M6: =(C6*Parametros!$C$10+D6*Parametros!$C$11+E6*Parametros!$C$12+F6*Parametros!$C$13)/SUM(Parametros!$C$10:$C$13) -> 0.73019777 | N6: =N5+(Parametros!$D$10*Forecast!D4*(1+(Parametros!$C$4+Parametros!$C$6)*Forecast!$C4)-Parametros!$E$10*Forecast!E4)/100 -> 0.7962952 | O6: =O5+(Parametros!$D$11*Forecast!F4*(1+(Parametros!$C$4+Parametros!$C$6)*Forecast!$C4)-Parametros!$E$11*Forecast!G4)/100 -> 0.70338122 | P6: =P5+(Parametros!$D$12*Forecast!H4*(1+(Parametros!$C$4+Parametros!$C$6)*Forecast!$C4)-Parametros!$E$12*Forecast!I4)/100 -> 0.6604467 | Q6: =Q5+(Parametros!$D$13*Forecast!J4*(1+(Parametros!$C$4+Parametros!$C$6)*Forecast!$C4)-Parametros!$E$13*Forecast!K4)/100 -> 0.71040179 | R6: =R5+(Parametros!$D$14*Forecast!L4*(1+(Parametros!$C$4+Parametros!$C$6)*Forecast!$C4)-Parametros!$E$14*Forecast!M4)/100 -> 0.63496172
A7: =Forecast!A5 -> 2025 | B7: =Forecast!B5 -> 44 | C7: =C6+(Parametros!$D$10*Forecast!D5*(1+Parametros!$C$4*Forecast!$C5)-Parametros!$E$10*Forecast!E5)/100 -> 0.76134326 | D7: =D6+(Parametros!$D$11*Forecast!F5*(1+Parametros!$C$4*Forecast!$C5)-Parametros!$E$11*Forecast!G5)/100 -> 0.66529554 | E7: =E6+(Parametros!$D$12*Forecast!H5*(1+Parametros!$C$4*Forecast!$C5)-Parametros!$E$12*Forecast!I5)/100 -> 0.61462956 | F7: =F6+(Parametros!$D$13*Forecast!J5*(1+Parametros!$C$4*Forecast!$C5)-Parametros!$E$13*Forecast!K5)/100 -> 0.72498412 | G7: =G6+(Parametros!$D$14*Forecast!L5*(1+Parametros!$C$4*Forecast!$C5)-Parametros!$E$14*Forecast!M5)/100 -> 0.60461347 | H7: =MAX(0,C7-1)*Parametros!$C$10 -> 0 | I7: =MAX(0,D7-1)*Parametros!$C$11 -> 0 | J7: =MAX(0,E7-1)*Parametros!$C$12 -> 0 | K7: =MAX(0,F7-1)*Parametros!$C$13 -> 0 | L7: =MAX(0,G7-1)*Parametros!$C$14 -> 0 | M7: =(C7*Parametros!$C$10+D7*Parametros!$C$11+E7*Parametros!$C$12+F7*Parametros!$C$13)/SUM(Parametros!$C$10:$C$13) -> 0.71631619 | N7: =N6+(Parametros!$D$10*Forecast!D5*(1+(Parametros!$C$4+Parametros!$C$6)*Forecast!$C5)-Parametros!$E$10*Forecast!E5)/100 -> 0.79515325 | O7: =O6+(Parametros!$D$11*Forecast!F5*(1+(Parametros!$C$4+Parametros!$C$6)*Forecast!$C5)-Parametros!$E$11*Forecast!G5)/100 -> 0.69828945 | P7: =P6+(Parametros!$D$12*Forecast!H5*(1+(Parametros!$C$4+Parametros!$C$6)*Forecast!$C5)-Parametros!$E$12*Forecast!I5)/100 -> 0.64720034 | Q7: =Q6+(Parametros!$D$13*Forecast!J5*(1+(Parametros!$C$4+Parametros!$C$6)*Forecast!$C5)-Parametros!$E$13*Forecast!K5)/100 -> 0.74834788 | R7: =R6+(Parametros!$D$14*Forecast!L5*(1+(Parametros!$C$4+Parametros!$C$6)*Forecast!$C5)-Parametros!$E$14*Forecast!M5)/100 -> 0.63129699
A8: =Forecast!A6 -> 2025 | B8: =Forecast!B6 -> 45 | C8: =C7+(Parametros!$D$10*Forecast!D6*(1+Parametros!$C$4*Forecast!$C6)-Parametros!$E$10*Forecast!E6)/100 -> 0.75886443 | D8: =D7+(Parametros!$D$11*Forecast!F6*(1+Parametros!$C$4*Forecast!$C6)-Parametros!$E$11*Forecast!G6)/100 -> 0.6411594 | E8: =E7+(Parametros!$D$12*Forecast!H6*(1+Parametros!$C$4*Forecast!$C6)-Parametros!$E$12*Forecast!I6)/100 -> 0.58735099 | F8: =F7+(Parametros!$D$13*Forecast!J6*(1+Parametros!$C$4*Forecast!$C6)-Parametros!$E$13*Forecast!K6)/100 -> 0.76462743 | G8: =G7+(Parametros!$D$14*Forecast!L6*(1+Parametros!$C$4*Forecast!$C6)-Parametros!$E$14*Forecast!M6)/100 -> 0.60272214 | H8: =MAX(0,C8-1)*Parametros!$C$10 -> 0 | I8: =MAX(0,D8-1)*Parametros!$C$11 -> 0 | J8: =MAX(0,E8-1)*Parametros!$C$12 -> 0 | K8: =MAX(0,F8-1)*Parametros!$C$13 -> 0 | L8: =MAX(0,G8-1)*Parametros!$C$14 -> 0 | M8: =(C8*Parametros!$C$10+D8*Parametros!$C$11+E8*Parametros!$C$12+F8*Parametros!$C$13)/SUM(Parametros!$C$10:$C$13) -> 0.71276311 | N8: =N7+(Parametros!$D$10*Forecast!D6*(1+(Parametros!$C$4+Parametros!$C$6)*Forecast!$C6)-Parametros!$E$10*Forecast!E6)/100 -> 0.81115781 | O8: =O7+(Parametros!$D$11*Forecast!F6*(1+(Parametros!$C$4+Parametros!$C$6)*Forecast!$C6)-Parametros!$E$11*Forecast!G6)/100 -> 0.69141877 | P8: =P7+(Parametros!$D$12*Forecast!H6*(1+(Parametros!$C$4+Parametros!$C$6)*Forecast!$C6)-Parametros!$E$12*Forecast!I6)/100 -> 0.63650588 | Q8: =Q7+(Parametros!$D$13*Forecast!J6*(1+(Parametros!$C$4+Parametros!$C$6)*Forecast!$C6)-Parametros!$E$13*Forecast!K6)/100 -> 0.80318983 | R8: =R7+(Parametros!$D$14*Forecast!L6*(1+(Parametros!$C$4+Parametros!$C$6)*Forecast!$C6)-Parametros!$E$14*Forecast!M6)/100 -> 0.64478375
A9: =Forecast!A7 -> 2025 | B9: =Forecast!B7 -> 46 | C9: =C8+(Parametros!$D$10*Forecast!D7*(1+Parametros!$C$4*Forecast!$C7)-Parametros!$E$10*Forecast!E7)/100 -> 0.80807388 | D9: =D8+(Parametros!$D$11*Forecast!F7*(1+Parametros!$C$4*Forecast!$C7)-Parametros!$E$11*Forecast!G7)/100 -> 0.67794961 | E9: =E8+(Parametros!$D$12*Forecast!H7*(1+Parametros!$C$4*Forecast!$C7)-Parametros!$E$12*Forecast!I7)/100 -> 0.57737903 | F9: =F8+(Parametros!$D$13*Forecast!J7*(1+Parametros!$C$4*Forecast!$C7)-Parametros!$E$13*Forecast!K7)/100 -> 0.81426463 | G9: =G8+(Parametros!$D$14*Forecast!L7*(1+Parametros!$C$4*Forecast!$C7)-Parametros!$E$14*Forecast!M7)/100 -> 0.63290021 | H9: =MAX(0,C9-1)*Parametros!$C$10 -> 0 | I9: =MAX(0,D9-1)*Parametros!$C$11 -> 0 | J9: =MAX(0,E9-1)*Parametros!$C$12 -> 0 | K9: =MAX(0,F9-1)*Parametros!$C$13 -> 0 | L9: =MAX(0,G9-1)*Parametros!$C$14 -> 0 | M9: =(C9*Parametros!$C$10+D9*Parametros!$C$11+E9*Parametros!$C$12+F9*Parametros!$C$13)/SUM(Parametros!$C$10:$C$13) -> 0.75145774 | N9: =N8+(Parametros!$D$10*Forecast!D7*(1+(Parametros!$C$4+Parametros!$C$6)*Forecast!$C7)-Parametros!$E$10*Forecast!E7)/100 -> 0.88437046 | O9: =O8+(Parametros!$D$11*Forecast!F7*(1+(Parametros!$C$4+Parametros!$C$6)*Forecast!$C7)-Parametros!$E$11*Forecast!G7)/100 -> 0.75073405 | P9: =P8+(Parametros!$D$12*Forecast!H7*(1+(Parametros!$C$4+Parametros!$C$6)*Forecast!$C7)-Parametros!$E$12*Forecast!I7)/100 -> 0.64460425 | Q9: =Q8+(Parametros!$D$13*Forecast!J7*(1+(Parametros!$C$4+Parametros!$C$6)*Forecast!$C7)-Parametros!$E$13*Forecast!K7)/100 -> 0.86906268 | R9: =R8+(Parametros!$D$14*Forecast!L7*(1+(Parametros!$C$4+Parametros!$C$6)*Forecast!$C7)-Parametros!$E$14*Forecast!M7)/100 -> 0.69291076
A10: =Forecast!A8 -> 2025 | B10: =Forecast!B8 -> 47 | C10: =C9+(Parametros!$D$10*Forecast!D8*(1+Parametros!$C$4*Forecast!$C8)-Parametros!$E$10*Forecast!E8)/100 -> 0.86882033 | D10: =D9+(Parametros!$D$11*Forecast!F8*(1+Parametros!$C$4*Forecast!$C8)-Parametros!$E$11*Forecast!G8)/100 -> 0.71912968 | E10: =E9+(Parametros!$D$12*Forecast!H8*(1+Parametros!$C$4*Forecast!$C8)-Parametros!$E$12*Forecast!I8)/100 -> 0.58125985 | F10: =F9+(Parametros!$D$13*Forecast!J8*(1+Parametros!$C$4*Forecast!$C8)-Parametros!$E$13*Forecast!K8)/100 -> 0.85092052 | G10: =G9+(Parametros!$D$14*Forecast!L8*(1+Parametros!$C$4*Forecast!$C8)-Parametros!$E$14*Forecast!M8)/100 -> 0.72879961 | H10: =MAX(0,C10-1)*Parametros!$C$10 -> 0 | I10: =MAX(0,D10-1)*Parametros!$C$11 -> 0 | J10: =MAX(0,E10-1)*Parametros!$C$12 -> 0 | K10: =MAX(0,F10-1)*Parametros!$C$13 -> 0 | L10: =MAX(0,G10-1)*Parametros!$C$14 -> 0 | M10: =(C10*Parametros!$C$10+D10*Parametros!$C$11+E10*Parametros!$C$12+F10*Parametros!$C$13)/SUM(Parametros!$C$10:$C$13) -> 0.79670553 | N10: =N9+(Parametros!$D$10*Forecast!D8*(1+(Parametros!$C$4+Parametros!$C$6)*Forecast!$C8)-Parametros!$E$10*Forecast!E8)/100 -> 0.96982233 | O10: =O9+(Parametros!$D$11*Forecast!F8*(1+(Parametros!$C$4+Parametros!$C$6)*Forecast!$C8)-Parametros!$E$11*Forecast!G8)/100 -> 0.81569358 | P10: =P9+(Parametros!$D$12*Forecast!H8*(1+(Parametros!$C$4+Parametros!$C$6)*Forecast!$C8)-Parametros!$E$12*Forecast!I8)/100 -> 0.66937888 | Q10: =Q9+(Parametros!$D$13*Forecast!J8*(1+(Parametros!$C$4+Parametros!$C$6)*Forecast!$C8)-Parametros!$E$13*Forecast!K8)/100 -> 0.92117997 | R10: =R9+(Parametros!$D$14*Forecast!L8*(1+(Parametros!$C$4+Parametros!$C$6)*Forecast!$C8)-Parametros!$E$14*Forecast!M8)/100 -> 0.8137259
A11: =Forecast!A9 -> 2025 | B11: =Forecast!B9 -> 48 | C11: =C10+(Parametros!$D$10*Forecast!D9*(1+Parametros!$C$4*Forecast!$C9)-Parametros!$E$10*Forecast!E9)/100 -> 0.9559316 | D11: =D10+(Parametros!$D$11*Forecast!F9*(1+Parametros!$C$4*Forecast!$C9)-Parametros!$E$11*Forecast!G9)/100 -> 0.79618535 | E11: =E10+(Parametros!$D$12*Forecast!H9*(1+Parametros!$C$4*Forecast!$C9)-Parametros!$E$12*Forecast!I9)/100 -> 0.62097889 | F11: =F10+(Parametros!$D$13*Forecast!J9*(1+Parametros!$C$4*Forecast!$C9)-Parametros!$E$13*Forecast!K9)/100 -> 0.868758 | G11: =G10+(Parametros!$D$14*Forecast!L9*(1+Parametros!$C$4*Forecast!$C9)-Parametros!$E$14*Forecast!M9)/100 -> 0.81834439 | H11: =MAX(0,C11-1)*Parametros!$C$10 -> 0 | I11: =MAX(0,D11-1)*Parametros!$C$11 -> 0 | J11: =MAX(0,E11-1)*Parametros!$C$12 -> 0 | K11: =MAX(0,F11-1)*Parametros!$C$13 -> 0 | L11: =MAX(0,G11-1)*Parametros!$C$14 -> 0 | M11: =(C11*Parametros!$C$10+D11*Parametros!$C$11+E11*Parametros!$C$12+F11*Parametros!$C$13)/SUM(Parametros!$C$10:$C$13) -> 0.86438246 | N11: =N10+(Parametros!$D$10*Forecast!D9*(1+(Parametros!$C$4+Parametros!$C$6)*Forecast!$C9)-Parametros!$E$10*Forecast!E9)/100 -> 1.0844547 | O11: =O10+(Parametros!$D$11*Forecast!F9*(1+(Parametros!$C$4+Parametros!$C$6)*Forecast!$C9)-Parametros!$E$11*Forecast!G9)/100 -> 0.91897062 | P11: =P10+(Parametros!$D$12*Forecast!H9*(1+(Parametros!$C$4+Parametros!$C$6)*Forecast!$C9)-Parametros!$E$12*Forecast!I9)/100 -> 0.73205412 | Q11: =Q10+(Parametros!$D$13*Forecast!J9*(1+(Parametros!$C$4+Parametros!$C$6)*Forecast!$C9)-Parametros!$E$13*Forecast!K9)/100 -> 0.95384472 | R11: =R10+(Parametros!$D$14*Forecast!L9*(1+(Parametros!$C$4+Parametros!$C$6)*Forecast!$C9)-Parametros!$E$14*Forecast!M9)/100 -> 0.92881739
A12: =Forecast!A10 -> 2025 | B12: =Forecast!B10 -> 49 | C12: =C11+(Parametros!$D$10*Forecast!D10*(1+Parametros!$C$4*Forecast!$C10)-Parametros!$E$10*Forecast!E10)/100 -> 1.0090664 | D12: =D11+(Parametros!$D$11*Forecast!F10*(1+Parametros!$C$4*Forecast!$C10)-Parametros!$E$11*Forecast!G10)/100 -> 0.84725892 | E12: =E11+(Parametros!$D$12*Forecast!H10*(1+Parametros!$C$4*Forecast!$C10)-Parametros!$E$12*Forecast!I10)/100 -> 0.65407553 | F12: =F11+(Parametros!$D$13*Forecast!J10*(1+Parametros!$C$4*Forecast!$C10)-Parametros!$E$13*Forecast!K10)/100 -> 0.85903494 | G12: =G11+(Parametros!$D$14*Forecast!L10*(1+Parametros!$C$4*Forecast!$C10)-Parametros!$E$14*Forecast!M10)/100 -> 0.88371169 | H12: =MAX(0,C12-1)*Parametros!$C$10 -> 43.518508 | I12: =MAX(0,D12-1)*Parametros!$C$11 -> 0 | J12: =MAX(0,E12-1)*Parametros!$C$12 -> 0 | K12: =MAX(0,F12-1)*Parametros!$C$13 -> 0 | L12: =MAX(0,G12-1)*Parametros!$C$14 -> 0 | M12: =(C12*Parametros!$C$10+D12*Parametros!$C$11+E12*Parametros!$C$12+F12*Parametros!$C$13)/SUM(Parametros!$C$10:$C$13) -> 0.90443801 | N12: =N11+(Parametros!$D$10*Forecast!D10*(1+(Parametros!$C$4+Parametros!$C$6)*Forecast!$C10)-Parametros!$E$10*Forecast!E10)/100 -> 1.1626485 | O12: =O11+(Parametros!$D$11*Forecast!F10*(1+(Parametros!$C$4+Parametros!$C$6)*Forecast!$C10)-Parametros!$E$11*Forecast!G10)/100 -> 0.99756486 | P12: =P11+(Parametros!$D$12*Forecast!H10*(1+(Parametros!$C$4+Parametros!$C$6)*Forecast!$C10)-Parametros!$E$12*Forecast!I10)/100 -> 0.78835574 | Q12: =Q11+(Parametros!$D$13*Forecast!J10*(1+(Parametros!$C$4+Parametros!$C$6)*Forecast!$C10)-Parametros!$E$13*Forecast!K10)/100 -> 0.955669 | R12: =R11+(Parametros!$D$14*Forecast!L10*(1+(Parametros!$C$4+Parametros!$C$6)*Forecast!$C10)-Parametros!$E$14*Forecast!M10)/100 -> 1.0166339
A13: =Forecast!A11 -> 2025 | B13: =Forecast!B11 -> 50 | C13: =C12+(Parametros!$D$10*Forecast!D11*(1+Parametros!$C$4*Forecast!$C11)-Parametros!$E$10*Forecast!E11)/100 -> 1.0683896 | D13: =D12+(Parametros!$D$11*Forecast!F11*(1+Parametros!$C$4*Forecast!$C11)-Parametros!$E$11*Forecast!G11)/100 -> 0.87731864 | E13: =E12+(Parametros!$D$12*Forecast!H11*(1+Parametros!$C$4*Forecast!$C11)-Parametros!$E$12*Forecast!I11)/100 -> 0.6788217 | F13: =F12+(Parametros!$D$13*Forecast!J11*(1+Parametros!$C$4*Forecast!$C11)-Parametros!$E$13*Forecast!K11)/100 -> 0.84419235 | G13: =G12+(Parametros!$D$14*Forecast!L11*(1+Parametros!$C$4*Forecast!$C11)-Parametros!$E$14*Forecast!M11)/100 -> 0.94272249 | H13: =MAX(0,C13-1)*Parametros!$C$10 -> 328.26999 | I13: =MAX(0,D13-1)*Parametros!$C$11 -> 0 | J13: =MAX(0,E13-1)*Parametros!$C$12 -> 0 | K13: =MAX(0,F13-1)*Parametros!$C$13 -> 0 | L13: =MAX(0,G13-1)*Parametros!$C$14 -> 0 | M13: =(C13*Parametros!$C$10+D13*Parametros!$C$11+E13*Parametros!$C$12+F13*Parametros!$C$13)/SUM(Parametros!$C$10:$C$13) -> 0.94146654 | N13: =N12+(Parametros!$D$10*Forecast!D11*(1+(Parametros!$C$4+Parametros!$C$6)*Forecast!$C11)-Parametros!$E$10*Forecast!E11)/100 -> 1.2481316 | O13: =O12+(Parametros!$D$11*Forecast!F11*(1+(Parametros!$C$4+Parametros!$C$6)*Forecast!$C11)-Parametros!$E$11*Forecast!G11)/100 -> 1.0517634 | P13: =P12+(Parametros!$D$12*Forecast!H11*(1+(Parametros!$C$4+Parametros!$C$6)*Forecast!$C11)-Parametros!$E$12*Forecast!I11)/100 -> 0.83798299 | Q13: =Q12+(Parametros!$D$13*Forecast!J11*(1+(Parametros!$C$4+Parametros!$C$6)*Forecast!$C11)-Parametros!$E$13*Forecast!K11)/100 -> 0.95160861 | R13: =R12+(Parametros!$D$14*Forecast!L11*(1+(Parametros!$C$4+Parametros!$C$6)*Forecast!$C11)-Parametros!$E$14*Forecast!M11)/100 -> 1.0978488
A14: =Forecast!A12 -> 2025 | B14: =Forecast!B12 -> 51 | C14: =C13+(Parametros!$D$10*Forecast!D12*(1+Parametros!$C$4*Forecast!$C12)-Parametros!$E$10*Forecast!E12)/100 -> 1.0986197 | D14: =D13+(Parametros!$D$11*Forecast!F12*(1+Parametros!$C$4*Forecast!$C12)-Parametros!$E$11*Forecast!G12)/100 -> 0.87362369 | E14: =E13+(Parametros!$D$12*Forecast!H12*(1+Parametros!$C$4*Forecast!$C12)-Parametros!$E$12*Forecast!I12)/100 -> 0.68768867 | F14: =F13+(Parametros!$D$13*Forecast!J12*(1+Parametros!$C$4*Forecast!$C12)-Parametros!$E$13*Forecast!K12)/100 -> 0.80654116 | G14: =G13+(Parametros!$D$14*Forecast!L12*(1+Parametros!$C$4*Forecast!$C12)-Parametros!$E$14*Forecast!M12)/100 -> 0.94419728 | H14: =MAX(0,C14-1)*Parametros!$C$10 -> 473.37462 | I14: =MAX(0,D14-1)*Parametros!$C$11 -> 0 | J14: =MAX(0,E14-1)*Parametros!$C$12 -> 0 | K14: =MAX(0,F14-1)*Parametros!$C$13 -> 0 | L14: =MAX(0,G14-1)*Parametros!$C$14 -> 0 | M14: =(C14*Parametros!$C$10+D14*Parametros!$C$11+E14*Parametros!$C$12+F14*Parametros!$C$13)/SUM(Parametros!$C$10:$C$13) -> 0.95127017 | N14: =N13+(Parametros!$D$10*Forecast!D12*(1+(Parametros!$C$4+Parametros!$C$6)*Forecast!$C12)-Parametros!$E$10*Forecast!E12)/100 -> 1.3034515 | O14: =O13+(Parametros!$D$11*Forecast!F12*(1+(Parametros!$C$4+Parametros!$C$6)*Forecast!$C12)-Parametros!$E$11*Forecast!G12)/100 -> 1.0678174 | P14: =P13+(Parametros!$D$12*Forecast!H12*(1+(Parametros!$C$4+Parametros!$C$6)*Forecast!$C12)-Parametros!$E$12*Forecast!I12)/100 -> 0.86900575 | Q14: =Q13+(Parametros!$D$13*Forecast!J12*(1+(Parametros!$C$4+Parametros!$C$6)*Forecast!$C12)-Parametros!$E$13*Forecast!K12)/100 -> 0.92208541 | R14: =R13+(Parametros!$D$14*Forecast!L12*(1+(Parametros!$C$4+Parametros!$C$6)*Forecast!$C12)-Parametros!$E$14*Forecast!M12)/100 -> 1.1163756
A15: =Forecast!A13 -> 2025 | B15: =Forecast!B13 -> 52 | C15: =C14+(Parametros!$D$10*Forecast!D13*(1+Parametros!$C$4*Forecast!$C13)-Parametros!$E$10*Forecast!E13)/100 -> 1.0774158 | D15: =D14+(Parametros!$D$11*Forecast!F13*(1+Parametros!$C$4*Forecast!$C13)-Parametros!$E$11*Forecast!G13)/100 -> 0.85368766 | E15: =E14+(Parametros!$D$12*Forecast!H13*(1+Parametros!$C$4*Forecast!$C13)-Parametros!$E$12*Forecast!I13)/100 -> 0.68285909 | F15: =F14+(Parametros!$D$13*Forecast!J13*(1+Parametros!$C$4*Forecast!$C13)-Parametros!$E$13*Forecast!K13)/100 -> 0.75386765 | G15: =G14+(Parametros!$D$14*Forecast!L13*(1+Parametros!$C$4*Forecast!$C13)-Parametros!$E$14*Forecast!M13)/100 -> 0.90611826 | H15: =MAX(0,C15-1)*Parametros!$C$10 -> 371.59593 | I15: =MAX(0,D15-1)*Parametros!$C$11 -> 0 | J15: =MAX(0,E15-1)*Parametros!$C$12 -> 0 | K15: =MAX(0,F15-1)*Parametros!$C$13 -> 0 | L15: =MAX(0,G15-1)*Parametros!$C$14 -> 0 | M15: =(C15*Parametros!$C$10+D15*Parametros!$C$11+E15*Parametros!$C$12+F15*Parametros!$C$13)/SUM(Parametros!$C$10:$C$13) -> 0.92759166 | N15: =N14+(Parametros!$D$10*Forecast!D13*(1+(Parametros!$C$4+Parametros!$C$6)*Forecast!$C13)-Parametros!$E$10*Forecast!E13)/100 -> 1.2822476 | O15: =O14+(Parametros!$D$11*Forecast!F13*(1+(Parametros!$C$4+Parametros!$C$6)*Forecast!$C13)-Parametros!$E$11*Forecast!G13)/100 -> 1.0478814 | P15: =P14+(Parametros!$D$12*Forecast!H13*(1+(Parametros!$C$4+Parametros!$C$6)*Forecast!$C13)-Parametros!$E$12*Forecast!I13)/100 -> 0.86417616 | Q15: =Q14+(Parametros!$D$13*Forecast!J13*(1+(Parametros!$C$4+Parametros!$C$6)*Forecast!$C13)-Parametros!$E$13*Forecast!K13)/100 -> 0.8694119 | R15: =R14+(Parametros!$D$14*Forecast!L13*(1+(Parametros!$C$4+Parametros!$C$6)*Forecast!$C13)-Parametros!$E$14*Forecast!M13)/100 -> 1.0782966
A16: =Forecast!A14 -> 2026 | B16: =Forecast!B14 -> 1 | C16: =C15+(Parametros!$D$10*Forecast!D14*(1+Parametros!$C$4*Forecast!$C14)-Parametros!$E$10*Forecast!E14)/100 -> 1.0228012 | D16: =D15+(Parametros!$D$11*Forecast!F14*(1+Parametros!$C$4*Forecast!$C14)-Parametros!$E$11*Forecast!G14)/100 -> 0.80694618 | E16: =E15+(Parametros!$D$12*Forecast!H14*(1+Parametros!$C$4*Forecast!$C14)-Parametros!$E$12*Forecast!I14)/100 -> 0.65273918 | F16: =F15+(Parametros!$D$13*Forecast!J14*(1+Parametros!$C$4*Forecast!$C14)-Parametros!$E$13*Forecast!K14)/100 -> 0.70052104 | G16: =G15+(Parametros!$D$14*Forecast!L14*(1+Parametros!$C$4*Forecast!$C14)-Parametros!$E$14*Forecast!M14)/100 -> 0.85331946 | H16: =MAX(0,C16-1)*Parametros!$C$10 -> 109.44598 | I16: =MAX(0,D16-1)*Parametros!$C$11 -> 0 | J16: =MAX(0,E16-1)*Parametros!$C$12 -> 0 | K16: =MAX(0,F16-1)*Parametros!$C$13 -> 0 | L16: =MAX(0,G16-1)*Parametros!$C$14 -> 0 | M16: =(C16*Parametros!$C$10+D16*Parametros!$C$11+E16*Parametros!$C$12+F16*Parametros!$C$13)/SUM(Parametros!$C$10:$C$13) -> 0.87810381 | N16: =N15+(Parametros!$D$10*Forecast!D14*(1+(Parametros!$C$4+Parametros!$C$6)*Forecast!$C14)-Parametros!$E$10*Forecast!E14)/100 -> 1.2276331 | O16: =O15+(Parametros!$D$11*Forecast!F14*(1+(Parametros!$C$4+Parametros!$C$6)*Forecast!$C14)-Parametros!$E$11*Forecast!G14)/100 -> 1.0011399 | P16: =P15+(Parametros!$D$12*Forecast!H14*(1+(Parametros!$C$4+Parametros!$C$6)*Forecast!$C14)-Parametros!$E$12*Forecast!I14)/100 -> 0.83405625 | Q16: =Q15+(Parametros!$D$13*Forecast!J14*(1+(Parametros!$C$4+Parametros!$C$6)*Forecast!$C14)-Parametros!$E$13*Forecast!K14)/100 -> 0.81606529 | R16: =R15+(Parametros!$D$14*Forecast!L14*(1+(Parametros!$C$4+Parametros!$C$6)*Forecast!$C14)-Parametros!$E$14*Forecast!M14)/100 -> 1.0254978
A17: =Forecast!A15 -> 2026 | B17: =Forecast!B15 -> 2 | C17: =C16+(Parametros!$D$10*Forecast!D15*(1+Parametros!$C$4*Forecast!$C15)-Parametros!$E$10*Forecast!E15)/100 -> 0.93710745 | D17: =D16+(Parametros!$D$11*Forecast!F15*(1+Parametros!$C$4*Forecast!$C15)-Parametros!$E$11*Forecast!G15)/100 -> 0.75233013 | E17: =E16+(Parametros!$D$12*Forecast!H15*(1+Parametros!$C$4*Forecast!$C15)-Parametros!$E$12*Forecast!I15)/100 -> 0.60553266 | F17: =F16+(Parametros!$D$13*Forecast!J15*(1+Parametros!$C$4*Forecast!$C15)-Parametros!$E$13*Forecast!K15)/100 -> 0.65584749 | G17: =G16+(Parametros!$D$14*Forecast!L15*(1+Parametros!$C$4*Forecast!$C15)-Parametros!$E$14*Forecast!M15)/100 -> 0.77528105 | H17: =MAX(0,C17-1)*Parametros!$C$10 -> 0 | I17: =MAX(0,D17-1)*Parametros!$C$11 -> 0 | J17: =MAX(0,E17-1)*Parametros!$C$12 -> 0 | K17: =MAX(0,F17-1)*Parametros!$C$13 -> 0 | L17: =MAX(0,G17-1)*Parametros!$C$14 -> 0 | M17: =(C17*Parametros!$C$10+D17*Parametros!$C$11+E17*Parametros!$C$12+F17*Parametros!$C$13)/SUM(Parametros!$C$10:$C$13) -> 0.81036912 | N17: =N16+(Parametros!$D$10*Forecast!D15*(1+(Parametros!$C$4+Parametros!$C$6)*Forecast!$C15)-Parametros!$E$10*Forecast!E15)/100 -> 1.1419393 | O17: =O16+(Parametros!$D$11*Forecast!F15*(1+(Parametros!$C$4+Parametros!$C$6)*Forecast!$C15)-Parametros!$E$11*Forecast!G15)/100 -> 0.94652388 | P17: =P16+(Parametros!$D$12*Forecast!H15*(1+(Parametros!$C$4+Parametros!$C$6)*Forecast!$C15)-Parametros!$E$12*Forecast!I15)/100 -> 0.78684973 | Q17: =Q16+(Parametros!$D$13*Forecast!J15*(1+(Parametros!$C$4+Parametros!$C$6)*Forecast!$C15)-Parametros!$E$13*Forecast!K15)/100 -> 0.77139174 | R17: =R16+(Parametros!$D$14*Forecast!L15*(1+(Parametros!$C$4+Parametros!$C$6)*Forecast!$C15)-Parametros!$E$14*Forecast!M15)/100 -> 0.94745938
... A28: =Forecast!A26 -> 2026 | B28: =Forecast!B26 -> 13 | C28: =C27+(Parametros!$D$10*Forecast!D26*(1+Parametros!$C$4*Forecast!$C26)-Parametros!$E$10*Forecast!E26)/100 -> 0.62178212 | D28: =D27+(Parametros!$D$11*Forecast!F26*(1+Parametros!$C$4*Forecast!$C26)-Parametros!$E$11*Forecast!G26)/100 -> 0.55408846 | E28: =E27+(Parametros!$D$12*Forecast!H26*(1+Parametros!$C$4*Forecast!$C26)-Parametros!$E$12*Forecast!I26)/100 -> 0.42250482 | F28: =F27+(Parametros!$D$13*Forecast!J26*(1+Parametros!$C$4*Forecast!$C26)-Parametros!$E$13*Forecast!K26)/100 -> 0.56185075 | G28: =G27+(Parametros!$D$14*Forecast!L26*(1+Parametros!$C$4*Forecast!$C26)-Parametros!$E$14*Forecast!M26)/100 -> 0.48283752 | H28: =MAX(0,C28-1)*Parametros!$C$10 -> 0 | I28: =MAX(0,D28-1)*Parametros!$C$11 -> 0 | J28: =MAX(0,E28-1)*Parametros!$C$12 -> 0 | K28: =MAX(0,F28-1)*Parametros!$C$13 -> 0 | L28: =MAX(0,G28-1)*Parametros!$C$14 -> 0 | M28: =(C28*Parametros!$C$10+D28*Parametros!$C$11+E28*Parametros!$C$12+F28*Parametros!$C$13)/SUM(Parametros!$C$10:$C$13) -> 0.57151102 | N28: =N27+(Parametros!$D$10*Forecast!D26*(1+(Parametros!$C$4+Parametros!$C$6)*Forecast!$C26)-Parametros!$E$10*Forecast!E26)/100 -> 0.82661395 | O28: =O27+(Parametros!$D$11*Forecast!F26*(1+(Parametros!$C$4+Parametros!$C$6)*Forecast!$C26)-Parametros!$E$11*Forecast!G26)/100 -> 0.7482822 | P28: =P27+(Parametros!$D$12*Forecast!H26*(1+(Parametros!$C$4+Parametros!$C$6)*Forecast!$C26)-Parametros!$E$12*Forecast!I26)/100 -> 0.60382189 | Q28: =Q27+(Parametros!$D$13*Forecast!J26*(1+(Parametros!$C$4+Parametros!$C$6)*Forecast!$C26)-Parametros!$E$13*Forecast!K26)/100 -> 0.677395 | R28: =R27+(Parametros!$D$14*Forecast!L26*(1+(Parametros!$C$4+Parametros!$C$6)*Forecast!$C26)-Parametros!$E$14*Forecast!M26)/100 -> 0.65501584

Sheet Semaforo
A1: Semáforo de la red
A2: Recibo adicional en la rampa: | C2: =Parametros!C4 -> 0
A4: Centro | B4: Ocupación hoy | C4: Pico | D4: Semana pico | E4: Semanas > 100 % | F4: Posiciones faltantes | G4: Cubrimiento alistamiento (mín. semanal) | H4: Cubrimiento alistamiento (total) | I4: Pico escenario alerta | J4: Estado
A5: CD-Norte | B5: =Parametros!F10 -> 0.8019 | C5: =MAX(Proyeccion!C$6:C$28) -> 1.0986197 | D5: =INDEX(Proyeccion!$A$6:$A$28,MATCH(C5,Proyeccion!C$6:C$28,0))&"-S"&TEXT(INDEX(Proyeccion!$B$6:$B$28,MATCH(C5,Proyeccion!C$6:C$28,0)),"00") -> 2025-S51 | E5: =COUNTIF(Proyeccion!C$6:C$28,">"&Parametros!$C$5) -> 5 | F5: =MAX(Proyeccion!H$6:H$28) -> 473.37462 | G5: =Parametros!I10/MAX(Forecast!E$4:E$26) -> 1.1079909 | H5: =Parametros!I10*COUNT(Forecast!E$4:E$26)/SUM(Forecast!E$4:E$26) -> 1.2620344 | I5: =MAX(Proyeccion!N$6:N$28) -> 1.3034515 | J5: =IF(C5>Parametros!$C$5,"Crítico",IF(I5>Parametros!$C$5,"Alerta","En control")) -> Crítico
A6: CD-Centro | B6: =Parametros!F11 -> 0.7078 | C6: =MAX(Proyeccion!D$6:D$28) -> 0.87731864 | D6: =INDEX(Proyeccion!$A$6:$A$28,MATCH(C6,Proyeccion!D$6:D$28,0))&"-S"&TEXT(INDEX(Proyeccion!$B$6:$B$28,MATCH(C6,Proyeccion!D$6:D$28,0)),"00") -> 2025-S50 | E6: =COUNTIF(Proyeccion!D$6:D$28,">"&Parametros!$C$5) -> 0 | F6: =MAX(Proyeccion!I$6:I$28) -> 0 | G6: =Parametros!I11/MAX(Forecast!G$4:G$26) -> 1.0385196 | H6: =Parametros!I11*COUNT(Forecast!G$4:G$26)/SUM(Forecast!G$4:G$26) -> 1.1736592 | I6: =MAX(Proyeccion!O$6:O$28) -> 1.0678174 | J6: =IF(C6>Parametros!$C$5,"Crítico",IF(I6>Parametros!$C$5,"Alerta","En control")) -> Alerta
A7: CD-Oriente | B7: =Parametros!F12 -> 0.6875 | C7: =MAX(Proyeccion!E$6:E$28) -> 0.68768867 | D7: =INDEX(Proyeccion!$A$6:$A$28,MATCH(C7,Proyeccion!E$6:E$28,0))&"-S"&TEXT(INDEX(Proyeccion!$B$6:$B$28,MATCH(C7,Proyeccion!E$6:E$28,0)),"00") -> 2025-S51 | E7: =COUNTIF(Proyeccion!E$6:E$28,">"&Parametros!$C$5) -> 0 | F7: =MAX(Proyeccion!J$6:J$28) -> 0 | G7: =Parametros!I12/MAX(Forecast!I$4:I$26) -> 1.0745645 | H7: =Parametros!I12*COUNT(Forecast!I$4:I$26)/SUM(Forecast!I$4:I$26) -> 1.1935834 | I7: =MAX(Proyeccion!P$6:P$28) -> 0.86900575 | J7: =IF(C7>Parametros!$C$5,"Crítico",IF(I7>Parametros!$C$5,"Alerta","En control")) -> En control
A8: CD-Bebidas | B8: =Parametros!F13 -> 0.7092 | C8: =MAX(Proyeccion!F$6:F$28) -> 0.868758 | D8: =INDEX(Proyeccion!$A$6:$A$28,MATCH(C8,Proyeccion!F$6:F$28,0))&"-S"&TEXT(INDEX(Proyeccion!$B$6:$B$28,MATCH(C8,Proyeccion!F$6:F$28,0)),"00") -> 2025-S48 | E8: =COUNTIF(Proyeccion!F$6:F$28,">"&Parametros!$C$5) -> 0 | F8: =MAX(Proyeccion!K$6:K$28) -> 0 | G8: =Parametros!I13/MAX(Forecast!K$4:K$26) -> 1.0303542 | H8: =Parametros!I13*COUNT(Forecast!K$4:K$26)/SUM(Forecast!K$4:K$26) -> 1.1668754 | I8: =MAX(Proyeccion!Q$6:Q$28) -> 0.955669 | J8: =IF(C8>Parametros!$C$5,"Crítico",IF(I8>Parametros!$C$5,"Alerta","En control")) -> En control
A9: OPL-Frio | B9: =Parametros!F14 -> 0.6306 | C9: =MAX(Proyeccion!G$6:G$28) -> 0.94419728 | D9: =INDEX(Proyeccion!$A$6:$A$28,MATCH(C9,Proyeccion!G$6:G$28,0))&"-S"&TEXT(INDEX(Proyeccion!$B$6:$B$28,MATCH(C9,Proyeccion!G$6:G$28,0)),"00") -> 2025-S51 | E9: =COUNTIF(Proyeccion!G$6:G$28,">"&Parametros!$C$5) -> 0 | F9: =MAX(Proyeccion!L$6:L$28) -> 0 | G9: =Parametros!I14/MAX(Forecast!M$4:M$26) -> 1.0046885 | H9: =Parametros!I14*COUNT(Forecast!M$4:M$26)/SUM(Forecast!M$4:M$26) -> 1.0948533 | I9: =MAX(Proyeccion!R$6:R$28) -> 1.1163756 | J9: =IF(C9>Parametros!$C$5,"Crítico",IF(I9>Parametros!$C$5,"Alerta","En control")) -> Alerta
A11: Red propia | C11: =MAX(Proyeccion!M6:M28) -> 0.95127017 | E11: =COUNTIF(Proyeccion!M6:M28,">"&Parametros!$C$5) -> 0
A13: Crítico: pico sobre el umbral en el escenario base. Alerta: lo supera solo con el recibo adicional del escenario de alerta (Parametros!C6).

Sheet Historico
A1: cd | B1: anio | C1: semana | D1: mes | E1: cajas_forecast | F1: cajas_real | G1: piezas_forecast | H1: piezas_real | I1: ocupacion | J1: recibo_imputado | K1: ocup_imputada | L1: semana_copiada | M1: valor_redondo | N1: periodo
A2: CD-Bebidas | B2: 2024 | C2: 1 | D2: 1 | E2: 8460 | F2: 8208 | G2: 41708 | H2: 38999 | I2: 0.6783 | J2: =FALSE() -> FALSE | K2: =FALSE() -> FALSE | L2: =FALSE() -> FALSE | M2: =FALSE() -> FALSE | N2: =IF(OR(AND(B2=2024,C2>=43),AND(B2=2025,C2<=13)),"Temporada 2024-25",IF(AND(B2=2025,C2>=36,C2<=42),"Sep-oct 2025","Resto del año")) -> Resto del año
A3: CD-Bebidas | B3: 2024 | C3: 2 | D3: 1 | E3: 7626 | F3: 8347 | G3: 34492 | H3: 36225 | I3: 0.6406 | J3: =FALSE() -> FALSE | K3: =FALSE() -> FALSE | L3: =FALSE() -> FALSE | M3: =FALSE() -> FALSE | N3: =IF(OR(AND(B3=2024,C3>=43),AND(B3=2025,C3<=13)),"Temporada 2024-25",IF(AND(B3=2025,C3>=36,C3<=42),"Sep-oct 2025","Resto del año")) -> Resto del año
A4: CD-Bebidas | B4: 2024 | C4: 3 | D4: 1 | E4: 10383 | F4: 10335 | G4: 33374 | H4: 35887 | I4: 0.6199 | J4: =FALSE() -> FALSE | K4: =FALSE() -> FALSE | L4: =FALSE() -> FALSE | M4: =FALSE() -> FALSE | N4: =IF(OR(AND(B4=2024,C4>=43),AND(B4=2025,C4<=13)),"Temporada 2024-25",IF(AND(B4=2025,C4>=36,C4<=42),"Sep-oct 2025","Resto del año")) -> Resto del año
A5: CD-Bebidas | B5: 2024 | C5: 4 | D5: 1 | E5: 12602 | F5: 12178 | G5: 41529 | H5: 38523 | I5: 0.6125 | J5: =FALSE() -> FALSE | K5: =FALSE() -> FALSE | L5: =FALSE() -> FALSE | M5: =FALSE() -> FALSE | N5: =IF(OR(AND(B5=2024,C5>=43),AND(B5=2025,C5<=13)),"Temporada 2024-25",IF(AND(B5=2025,C5>=36,C5<=42),"Sep-oct 2025","Resto del año")) -> Resto del año
A6: CD-Bebidas | B6: 2024 | C6: 5 | D6: 1 | E6: 11825 | F6: 15306 | G6: 42128 | H6: 39933 | I6: 0.6317 | J6: =FALSE() -> FALSE | K6: =FALSE() -> FALSE | L6: =FALSE() -> FALSE | M6: =FALSE() -> FALSE | N6: =IF(OR(AND(B6=2024,C6>=43),AND(B6=2025,C6<=13)),"Temporada 2024-25",IF(AND(B6=2025,C6>=36,C6<=42),"Sep-oct 2025","Resto del año")) -> Resto del año
A7: CD-Bebidas | B7: 2024 | C7: 6 | D7: 2 | E7: 14540 | F7: 15838 | G7: 39740 | H7: 39994 | I7: 0.6403 | J7: =FALSE() -> FALSE | K7: =FALSE() -> FALSE | L7: =FALSE() -> FALSE | M7: =FALSE() -> FALSE | N7: =IF(OR(AND(B7=2024,C7>=43),AND(B7=2025,C7<=13)),"Temporada 2024-25",IF(AND(B7=2025,C7>=36,C7<=42),"Sep-oct 2025","Resto del año")) -> Resto del año
A8: CD-Bebidas | B8: 2024 | C8: 7 | D8: 2 | E8: 17245 | F8: 16416 | G8: 39524 | H8: 41830 | I8: 0.6509 | J8: =FALSE() -> FALSE | K8: =FALSE() -> FALSE | L8: =FALSE() -> FALSE | M8: =FALSE() -> FALSE | N8: =IF(OR(AND(B8=2024,C8>=43),AND(B8=2025,C8<=13)),"Temporada 2024-25",IF(AND(B8=2025,C8>=36,C8<=42),"Sep-oct 2025","Resto del año")) -> Resto del año
A9: CD-Bebidas | B9: 2024 | C9: 8 | D9: 2 | E9: 14166 | F9: 15238 | G9: 42334 | H9: 39497 | I9: 0.6614 | J9: =FALSE() -> FALSE | K9: =FALSE() -> FALSE | L9: =FALSE() -> FALSE | M9: =FALSE() -> FALSE | N9: =IF(OR(AND(B9=2024,C9>=43),AND(B9=2025,C9<=13)),"Temporada 2024-25",IF(AND(B9=2025,C9>=36,C9<=42),"Sep-oct 2025","Resto del año")) -> Resto del año
A10: CD-Bebidas | B10: 2024 | C10: 9 | D10: 2 | E10: 16896 | F10: 16889 | G10: 42231 | H10: 42925 | I10: 0.6671 | J10: =FALSE() -> FALSE | K10: =FALSE() -> FALSE | L10: =FALSE() -> FALSE | M10: =FALSE() -> FALSE | N10: =IF(OR(AND(B10=2024,C10>=43),AND(B10=2025,C10<=13)),"Temporada 2024-25",IF(AND(B10=2025,C10>=36,C10<=42),"Sep-oct 2025","Resto del año")) -> Resto del año
A11: CD-Bebidas | B11: 2024 | C11: 10 | D11: 3 | E11: 15212 | F11: 16974 | G11: 47138 | H11: 45207 | I11: 0.6702 | J11: =FALSE() -> FALSE | K11: =FALSE() -> FALSE | L11: =FALSE() -> FALSE | M11: =FALSE() -> FALSE | N11: =IF(OR(AND(B11=2024,C11>=43),AND(B11=2025,C11<=13)),"Temporada 2024-25",IF(AND(B11=2025,C11>=36,C11<=42),"Sep-oct 2025","Resto del año")) -> Resto del año
A12: CD-Bebidas | B12: 2024 | C12: 11 | D12: 3 | E12: 15986 | F12: 17567 | G12: 44984 | H12: 44093 | I12: 0.6831 | J12: =FALSE() -> FALSE | K12: =FALSE() -> FALSE | L12: =FALSE() -> FALSE | M12: =FALSE() -> FALSE | N12: =IF(OR(AND(B12=2024,C12>=43),AND(B12=2025,C12<=13)),"Temporada 2024-25",IF(AND(B12=2025,C12>=36,C12<=42),"Sep-oct 2025","Resto del año")) -> Resto del año
A13: CD-Bebidas | B13: 2024 | C13: 12 | D13: 3 | E13: 20054 | F13: 19210 | G13: 48217 | H13: 46617 | I13: 0.6924 | J13: =FALSE() -> FALSE | K13: =FALSE() -> FALSE | L13: =FALSE() -> FALSE | M13: =FALSE() -> FALSE | N13: =IF(OR(AND(B13=2024,C13>=43),AND(B13=2025,C13<=13)),"Temporada 2024-25",IF(AND(B13=2025,C13>=36,C13<=42),"Sep-oct 2025","Resto del año")) -> Resto del año
... A111: CD-Centro | B111: 2024 | C111: 16 | D111: 4 | E111: 17046 | F111: 17743 | G111: 139418 | H111: 135224 | I111: 0.5522 | J111: =FALSE() -> FALSE | K111: =FALSE() -> FALSE | L111: =FALSE() -> FALSE | M111: =FALSE() -> FALSE | N111: =IF(OR(AND(B111=2024,C111>=43),AND(B111=2025,C111<=13)),"Temporada 2024-25",IF(AND(B111=2025,C111>=36,C111<=42),"Sep-oct 2025","Resto del año")) -> Resto del año
A112: CD-Centro | B112: 2024 | C112: 17 | D112: 4 | E112: 16232 | F112: 17673 | G112: 152025 | H112: 139959 | I112: 0.55925 | J112: =FALSE() -> FALSE | K112: =TRUE() -> TRUE | L112: =FALSE() -> FALSE | M112: =FALSE() -> FALSE | N112: =IF(OR(AND(B112=2024,C112>=43),AND(B112=2025,C112<=13)),"Temporada 2024-25",IF(AND(B112=2025,C112>=36,C112<=42),"Sep-oct 2025","Resto del año")) -> Resto del año
A113: CD-Centro | B113: 2024 | C113: 18 | D113: 4 | E113: 18353 | F113: 17422 | G113: 138875 | H113: 129657 | I113: 0.5663 | J113: =FALSE() -> FALSE | K113: =FALSE() -> FALSE | L113: =FALSE() -> FALSE | M113: =FALSE() -> FALSE | N113: =IF(OR(AND(B113=2024,C113>=43),AND(B113=2025,C113<=13)),"Temporada 2024-25",IF(AND(B113=2025,C113>=36,C113<=42),"Sep-oct 2025","Resto del año")) -> Resto del año
A114: CD-Centro | B114: 2024 | C114: 19 | D114: 5 | E114: 16341 | F114: 18551 | G114: 142959 | H114: 139671 | I114: 0.5658 | J114: =FALSE() -> FALSE | K114: =FALSE() -> FALSE | L114: =FALSE() -> FALSE | M114: =FALSE() -> FALSE | N114: =IF(OR(AND(B114=2024,C114>=43),AND(B114=2025,C114<=13)),"Temporada 2024-25",IF(AND(B114=2025,C114>=36,C114<=42),"Sep-oct 2025","Resto del año")) -> Resto del año
A115: CD-Centro | B115: 2024 | C115: 20 | D115: 5 | E115: 17564 | F115: 17395 | G115: 139152 | H115: 134805 | I115: 0.5665 | J115: =FALSE() -> FALSE | K115: =FALSE() -> FALSE | L115: =FALSE() -> FALSE | M115: =FALSE() -> FALSE | N115: =IF(OR(AND(B115=2024,C115>=43),AND(B115=2025,C115<=13)),"Temporada 2024-25",IF(AND(B115=2025,C115>=36,C115<=42),"Sep-oct 2025","Resto del año")) -> Resto del año
A116: CD-Centro | B116: 2024 | C116: 21 | D116: 5 | E116: 18498 | F116: 18868 | G116: 156013 | H116: 136454 | I116: 0.5872 | J116: =FALSE() -> FALSE | K116: =FALSE() -> FALSE | L116: =FALSE() -> FALSE | M116: =FALSE() -> FALSE | N116: =IF(OR(AND(B116=2024,C116>=43),AND(B116=2025,C116<=13)),"Temporada 2024-25",IF(AND(B116=2025,C116>=36,C116<=42),"Sep-oct 2025","Resto del año")) -> Resto del año
A117: CD-Centro | B117: 2024 | C117: 22 | D117: 5 | E117: 11892 | F117: 14466 | G117: 120707 | H117: 120823 | I117: 0.5796 | J117: =FALSE() -> FALSE | K117: =FALSE() -> FALSE | L117: =FALSE() -> FALSE | M117: =FALSE() -> FALSE | N117: =IF(OR(AND(B117=2024,C117>=43),AND(B117=2025,C117<=13)),"Temporada 2024-25",IF(AND(B117=2025,C117>=36,C117<=42),"Sep-oct 2025","Resto del año")) -> Resto del año
A118: CD-Centro | B118: 2024 | C118: 23 | D118: 6 | E118: 17487 | F118: 18151 | G118: 149734 | H118: 142979 | I118: 0.5764 | J118: =FALSE() -> FALSE | K118: =FALSE() -> FALSE | L118: =FALSE() -> FALSE | M118: =FALSE() -> FALSE | N118: =IF(OR(AND(B118=2024,C118>=43),AND(B118=2025,C118<=13)),"Temporada 2024-25",IF(AND(B118=2025,C118>=36,C118<=42),"Sep-oct 2025","Resto del año")) -> Resto del año
A119: CD-Centro | B119: 2024 | C119: 24 | D119: 6 | E119: 18813 | F119: 18529 | G119: 141483 | H119: 135623 | I119: 0.587 | J119: =FALSE() -> FALSE | K119: =FALSE() -> FALSE | L119: =FALSE() -> FALSE | M119: =FALSE() -> FALSE | N119: =IF(OR(AND(B119=2024,C119>=43),AND(B119=2025,C119<=13)),"Temporada 2024-25",IF(AND(B119=2025,C119>=36,C119<=42),"Sep-oct 2025","Resto del año")) -> Resto del año
A120: CD-Centro | B120: 2024 | C120: 25 | D120: 6 | E120: 16832 | F120: 17330 | G120: 137842 | H120: 133492 | I120: 0.5948 | J120: =FALSE() -> FALSE | K120: =FALSE() -> FALSE | L120: =FALSE() -> FALSE | M120: =FALSE() -> FALSE | N120: =IF(OR(AND(B120=2024,C120>=43),AND(B120=2025,C120<=13)),"Temporada 2024-25",IF(AND(B120=2025,C120>=36,C120<=42),"Sep-oct 2025","Resto del año")) -> Resto del año
A121: CD-Centro | B121: 2024 | C121: 26 | D121: 6 | E121: 15780 | F121: 16966 | G121: 131332 | H121: 128577 | I121: 0.5985 | J121: =FALSE() -> FALSE | K121: =FALSE() -> FALSE | L121: =FALSE() -> FALSE | M121: =FALSE() -> FALSE | N121: =IF(OR(AND(B121=2024,C121>=43),AND(B121=2025,C121<=13)),"Temporada 2024-25",IF(AND(B121=2025,C121>=36,C121<=42),"Sep-oct 2025","Resto del año")) -> Resto del año
A122: CD-Centro | B122: 2024 | C122: 27 | D122: 7 | E122: 17774 | F122: 17084 | G122: 140212 | H122: 137180 | I122: 0.5952 | J122: =FALSE() -> FALSE | K122: =FALSE() -> FALSE | L122: =FALSE() -> FALSE | M122: =FALSE() -> FALSE | N122: =IF(OR(AND(B122=2024,C122>=43),AND(B122=2025,C122<=13)),"Temporada 2024-25",IF(AND(B122=2025,C122>=36,C122<=42),"Sep-oct 2025","Resto del año")) -> Resto del año
A123: CD-Centro | B123: 2024 | C123: 28 | D123: 7 | E123: 16876 | F123: 18043 | G123: 135470 | H123: 131536 | I123: 0.6073 | J123: =FALSE() -> FALSE | K123: =FALSE() -> FALSE | L123: =FALSE() -> FALSE | M123: =FALSE() -> FALSE | N123: =IF(OR(AND(B123=2024,C123>=43),AND(B123=2025,C123<=13)),"Temporada 2024-25",IF(AND(B123=2025,C123>=36,C123<=42),"Sep-oct 2025","Resto del año")) -> Resto del año
A124: CD-Centro | B124: 2024 | C124: 29 | D124: 7 | E124: 16608 | F124: 18351 | G124: 133529 | H124: 135657 | I124: 0.6262 | J124: =FALSE() -> FALSE | K124: =FALSE() -> FALSE | L124: =FALSE() -> FALSE | M124: =FALSE() -> FALSE | N124: =IF(OR(AND(B124=2024,C124>=43),AND(B124=2025,C124<=13)),"Temporada 2024-25",IF(AND(B124=2025,C124>=36,C124<=42),"Sep-oct 2025","Resto del año")) -> Resto del año
... A130: CD-Centro | B130: 2024 | C130: 35 | D130: 8 | E130: 14139 | F130: 15795 | G130: 132654 | H130: 124778 | I130: 0.6257 | J130: =FALSE() -> FALSE | K130: =FALSE() -> FALSE | L130: =FALSE() -> FALSE | M130: =FALSE() -> FALSE | N130: =IF(OR(AND(B130=2024,C130>=43),AND(B130=2025,C130<=13)),"Temporada 2024-25",IF(AND(B130=2025,C130>=36,C130<=42),"Sep-oct 2025","Resto del año")) -> Resto del año
A131: CD-Centro | B131: 2024 | C131: 36 | D131: 9 | E131: 16918 | F131: 15795 | G131: 132355 | H131: 124778 | I131: 0.6239 | J131: =FALSE() -> FALSE | K131: =FALSE() -> FALSE | L131: =TRUE() -> TRUE | M131: =FALSE() -> FALSE | N131: =IF(OR(AND(B131=2024,C131>=43),AND(B131=2025,C131<=13)),"Temporada 2024-25",IF(AND(B131=2025,C131>=36,C131<=42),"Sep-oct 2025","Resto del año")) -> Resto del año
A132: CD-Centro | B132: 2024 | C132: 37 | D132: 9 | E132: 19809 | F132: 18650 | G132: 129928 | H132: 131733 | I132: 0.634 | J132: =FALSE() -> FALSE | K132: =FALSE() -> FALSE | L132: =FALSE() -> FALSE | M132: =FALSE() -> FALSE | N132: =IF(OR(AND(B132=2024,C132>=43),AND(B132=2025,C132<=13)),"Temporada 2024-25",IF(AND(B132=2025,C132>=36,C132<=42),"Sep-oct 2025","Resto del año")) -> Resto del año
A133: CD-Centro | B133: 2024 | C133: 38 | D133: 9 | E133: 16592 | F133: 17241 | G133: 130368 | H133: 137365 | I133: 0.6266 | J133: =FALSE() -> FALSE | K133: =FALSE() -> FALSE | L133: =FALSE() -> FALSE | M133: =FALSE() -> FALSE | N133: =IF(OR(AND(B133=2024,C133>=43),AND(B133=2025,C133<=13)),"Temporada 2024-25",IF(AND(B133=2025,C133>=36,C133<=42),"Sep-oct 2025","Resto del año")) -> Resto del año
A134: CD-Centro | B134: 2024 | C134: 39 | D134: 9 | E134: 15396 | F134: 15427 | G134: 121465 | H134: 123066 | I134: 0.6238 | J134: =FALSE() -> FALSE | K134: =FALSE() -> FALSE | L134: =FALSE() -> FALSE | M134: =FALSE() -> FALSE | N134: =IF(OR(AND(B134=2024,C134>=43),AND(B134=2025,C134<=13)),"Temporada 2024-25",IF(AND(B134=2025,C134>=36,C134<=42),"Sep-oct 2025","Resto del año")) -> Resto del año
A135: CD-Centro | B135: 2024 | C135: 40 | D135: 9 | E135: 13467 | F135: 16553 | G135: 131651 | H135: 127751 | I135: 0.6221 | J135: =FALSE() -> FALSE | K135: =FALSE() -> FALSE | L135: =FALSE() -> FALSE | M135: =FALSE() -> FALSE | N135: =IF(OR(AND(B135=2024,C135>=43),AND(B135=2025,C135<=13)),"Temporada 2024-25",IF(AND(B135=2025,C135>=36,C135<=42),"Sep-oct 2025","Resto del año")) -> Resto del año
A136: CD-Centro | B136: 2024 | C136: 41 | D136: 10 | E136: 13442 | F136: 16553 | G136: 130573 | H136: 130437 | I136: 0.6156 | J136: =FALSE() -> FALSE | K136: =FALSE() -> FALSE | L136: =FALSE() -> FALSE | M136: =FALSE() -> FALSE | N136: =IF(OR(AND(B136=2024,C136>=43),AND(B136=2025,C136<=13)),"Temporada 2024-25",IF(AND(B136=2025,C136>=36,C136<=42),"Sep-oct 2025","Resto del año")) -> Resto del año
A137: CD-Centro | B137: 2024 | C137: 42 | D137: 10 | E137: 13017 | F137: 17033 | G137: 125425 | H137: 126798 | I137: 0.6256 | J137: =FALSE() -> FALSE | K137: =FALSE() -> FALSE | L137: =FALSE() -> FALSE | M137: =FALSE() -> FALSE | N137: =IF(OR(AND(B137=2024,C137>=43),AND(B137=2025,C137<=13)),"Temporada 2024-25",IF(AND(B137=2025,C137>=36,C137<=42),"Sep-oct 2025","Resto del año")) -> Resto del año
A138: CD-Centro | B138: 2024 | C138: 43 | D138: 10 | E138: 12287 | F138: 17279 | G138: 129635 | H138: 131567 | I138: 0.624 | J138: =FALSE() -> FALSE | K138: =FALSE() -> FALSE | L138: =FALSE() -> FALSE | M138: =FALSE() -> FALSE | N138: =IF(OR(AND(B138=2024,C138>=43),AND(B138=2025,C138<=13)),"Temporada 2024-25",IF(AND(B138=2025,C138>=36,C138<=42),"Sep-oct 2025","Resto del año")) -> Temporada 2024-25
A139: CD-Centro | B139: 2024 | C139: 44 | D139: 10 | E139: 15933 | F139: 18812 | G139: 127839 | H139: 129807 | I139: 0.6493 | J139: =FALSE() -> FALSE | K139: =FALSE() -> FALSE | L139: =FALSE() -> FALSE | M139: =FALSE() -> FALSE | N139: =IF(OR(AND(B139=2024,C139>=43),AND(B139=2025,C139<=13)),"Temporada 2024-25",IF(AND(B139=2025,C139>=36,C139<=42),"Sep-oct 2025","Resto del año")) -> Temporada 2024-25
A140: CD-Centro | B140: 2024 | C140: 45 | D140: 11 | E140: 13717 | F140: 17746 | G140: 136516 | H140: 128414 | I140: 0.6678 | J140: =FALSE() -> FALSE | K140: =FALSE() -> FALSE | L140: =FALSE() -> FALSE | M140: =FALSE() -> FALSE | N140: =IF(OR(AND(B140=2024,C140>=43),AND(B140=2025,C140<=13)),"Temporada 2024-25",IF(AND(B140=2025,C140>=36,C140<=42),"Sep-oct 2025","Resto del año")) -> Temporada 2024-25
A141: CD-Centro | B141: 2024 | C141: 46 | D141: 11 | E141: 17860 | F141: 22136 | G141: 131413 | H141: 135551 | I141: 0.7143 | J141: =FALSE() -> FALSE | K141: =FALSE() -> FALSE | L141: =FALSE() -> FALSE | M141: =FALSE() -> FALSE | N141: =IF(OR(AND(B141=2024,C141>=43),AND(B141=2025,C141<=13)),"Temporada 2024-25",IF(AND(B141=2025,C141>=36,C141<=42),"Sep-oct 2025","Resto del año")) -> Temporada 2024-25
A142: CD-Centro | B142: 2024 | C142: 47 | D142: 11 | E142: 19482 | F142: 22840 | G142: 126418 | H142: 127890 | I142: 0.7765 | J142: =FALSE() -> FALSE | K142: =FALSE() -> FALSE | L142: =FALSE() -> FALSE | M142: =FALSE() -> FALSE | N142: =IF(OR(AND(B142=2024,C142>=43),AND(B142=2025,C142<=13)),"Temporada 2024-25",IF(AND(B142=2025,C142>=36,C142<=42),"Sep-oct 2025","Resto del año")) -> Temporada 2024-25
...

Sheet Cumplimiento
A1: Cumplimiento del forecast (real ÷ forecast)
A3: Centro | B3: Recibo · Resto del año | C3: Recibo · Temporada 2024-25 | D3: Recibo · Sep-oct 2025 | E3: Alistamiento · Resto del año | F3: Alistamiento · Temporada 2024-25 | G3: Alistamiento · Sep-oct 2025
A4: CD-Norte | B4: =SUMIFS(Historico!$F$2:$F$471,Historico!$A$2:$A$471,$A4,Historico!$N$2:$N$471,"Resto del año")/SUMIFS(Historico!$E$2:$E$471,Historico!$A$2:$A$471,$A4,Historico!$N$2:$N$471,"Resto del año") -> 1.0407117 | C4: =SUMIFS(Historico!$F$2:$F$471,Historico!$A$2:$A$471,$A4,Historico!$N$2:$N$471,"Temporada 2024-25")/SUMIFS(Historico!$E$2:$E$471,Historico!$A$2:$A$471,$A4,Historico!$N$2:$N$471,"Temporada 2024-25") -> 1.1160754 | D4: =SUMIFS(Historico!$F$2:$F$471,Historico!$A$2:$A$471,$A4,Historico!$N$2:$N$471,"Sep-oct 2025")/SUMIFS(Historico!$E$2:$E$471,Historico!$A$2:$A$471,$A4,Historico!$N$2:$N$471,"Sep-oct 2025") -> 1.1271479 | E4: =SUMIFS(Historico!$H$2:$H$471,Historico!$A$2:$A$471,$A4,Historico!$N$2:$N$471,"Resto del año")/SUMIFS(Historico!$G$2:$G$471,Historico!$A$2:$A$471,$A4,Historico!$N$2:$N$471,"Resto del año") -> 0.99083289 | F4: =SUMIFS(Historico!$H$2:$H$471,Historico!$A$2:$A$471,$A4,Historico!$N$2:$N$471,"Temporada 2024-25")/SUMIFS(Historico!$G$2:$G$471,Historico!$A$2:$A$471,$A4,Historico!$N$2:$N$471,"Temporada 2024-25") -> 0.9859632 | G4: =SUMIFS(Historico!$H$2:$H$471,Historico!$A$2:$A$471,$A4,Historico!$N$2:$N$471,"Sep-oct 2025")/SUMIFS(Historico!$G$2:$G$471,Historico!$A$2:$A$471,$A4,Historico!$N$2:$N$471,"Sep-oct 2025") -> 0.97428767
A5: CD-Centro | B5: =SUMIFS(Historico!$F$2:$F$471,Historico!$A$2:$A$471,$A5,Historico!$N$2:$N$471,"Resto del año")/SUMIFS(Historico!$E$2:$E$471,Historico!$A$2:$A$471,$A5,Historico!$N$2:$N$471,"Resto del año") -> 1.0382609 | C5: =SUMIFS(Historico!$F$2:$F$471,Historico!$A$2:$A$471,$A5,Historico!$N$2:$N$471,"Temporada 2024-25")/SUMIFS(Historico!$E$2:$E$471,Historico!$A$2:$A$471,$A5,Historico!$N$2:$N$471,"Temporada 2024-25") -> 1.1429367 | D5: =SUMIFS(Historico!$F$2:$F$471,Historico!$A$2:$A$471,$A5,Historico!$N$2:$N$471,"Sep-oct 2025")/SUMIFS(Historico!$E$2:$E$471,Historico!$A$2:$A$471,$A5,Historico!$N$2:$N$471,"Sep-oct 2025") -> 1.0581522 | E5: =SUMIFS(Historico!$H$2:$H$471,Historico!$A$2:$A$471,$A5,Historico!$N$2:$N$471,"Resto del año")/SUMIFS(Historico!$G$2:$G$471,Historico!$A$2:$A$471,$A5,Historico!$N$2:$N$471,"Resto del año") -> 0.98166389 | F5: =SUMIFS(Historico!$H$2:$H$471,Historico!$A$2:$A$471,$A5,Historico!$N$2:$N$471,"Temporada 2024-25")/SUMIFS(Historico!$G$2:$G$471,Historico!$A$2:$A$471,$A5,Historico!$N$2:$N$471,"Temporada 2024-25") -> 0.99683492 | G5: =SUMIFS(Historico!$H$2:$H$471,Historico!$A$2:$A$471,$A5,Historico!$N$2:$N$471,"Sep-oct 2025")/SUMIFS(Historico!$G$2:$G$471,Historico!$A$2:$A$471,$A5,Historico!$N$2:$N$471,"Sep-oct 2025") -> 0.97901128
A6: CD-Oriente | B6: =SUMIFS(Historico!$F$2:$F$471,Historico!$A$2:$A$471,$A6,Historico!$N$2:$N$471,"Resto del año")/SUMIFS(Historico!$E$2:$E$471,Historico!$A$2:$A$471,$A6,Historico!$N$2:$N$471,"Resto del año") -> 1.0343577 | C6: =SUMIFS(Historico!$F$2:$F$471,Historico!$A$2:$A$471,$A6,Historico!$N$2:$N$471,"Temporada 2024-25")/SUMIFS(Historico!$E$2:$E$471,Historico!$A$2:$A$471,$A6,Historico!$N$2:$N$471,"Temporada 2024-25") -> 1.0992358 | D6: =SUMIFS(Historico!$F$2:$F$471,Historico!$A$2:$A$471,$A6,Historico!$N$2:$N$471,"Sep-oct 2025")/SUMIFS(Historico!$E$2:$E$471,Historico!$A$2:$A$471,$A6,Historico!$N$2:$N$471,"Sep-oct 2025") -> 1.0785278 | E6: =SUMIFS(Historico!$H$2:$H$471,Historico!$A$2:$A$471,$A6,Historico!$N$2:$N$471,"Resto del año")/SUMIFS(Historico!$G$2:$G$471,Historico!$A$2:$A$471,$A6,Historico!$N$2:$N$471,"Resto del año") -> 0.99907183 | F6: =SUMIFS(Historico!$H$2:$H$471,Historico!$A$2:$A$471,$A6,Historico!$N$2:$N$471,"Temporada 2024-25")/SUMIFS(Historico!$G$2:$G$471,Historico!$A$2:$A$471,$A6,Historico!$N$2:$N$471,"Temporada 2024-25") -> 0.99471188 | G6: =SUMIFS(Historico!$H$2:$H$471,Historico!$A$2:$A$471,$A6,Historico!$N$2:$N$471,"Sep-oct 2025")/SUMIFS(Historico!$G$2:$G$471,Historico!$A$2:$A$471,$A6,Historico!$N$2:$N$471,"Sep-oct 2025") -> 1.0080519
A7: CD-Bebidas | B7: =SUMIFS(Historico!$F$2:$F$471,Historico!$A$2:$A$471,$A7,Historico!$N$2:$N$471,"Resto del año")/SUMIFS(Historico!$E$2:$E$471,Historico!$A$2:$A$471,$A7,Historico!$N$2:$N$471,"Resto del año") -> 1.0312661 | C7: =SUMIFS(Historico!$F$2:$F$471,Historico!$A$2:$A$471,$A7,Historico!$N$2:$N$471,"Temporada 2024-25")/SUMIFS(Historico!$E$2:$E$471,Historico!$A$2:$A$471,$A7,Historico!$N$2:$N$471,"Temporada 2024-25") -> 1.0982398 | D7: =SUMIFS(Historico!$F$2:$F$471,Historico!$A$2:$A$471,$A7,Historico!$N$2:$N$471,"Sep-oct 2025")/SUMIFS(Historico!$E$2:$E$471,Historico!$A$2:$A$471,$A7,Historico!$N$2:$N$471,"Sep-oct 2025") -> 1.1263187 | E7: =SUMIFS(Historico!$H$2:$H$471,Historico!$A$2:$A$471,$A7,Historico!$N$2:$N$471,"Resto del año")/SUMIFS(Historico!$G$2:$G$471,Historico!$A$2:$A$471,$A7,Historico!$N$2:$N$471,"Resto del año") -> 0.98177031 | F7: =SUMIFS(Historico!$H$2:$H$471,Historico!$A$2:$A$471,$A7,Historico!$N$2:$N$471,"Temporada 2024-25")/SUMIFS(Historico!$G$2:$G$471,Historico!$A$2:$A$471,$A7,Historico!$N$2:$N$471,"Temporada 2024-25") -> 0.99971954 | G7: =SUMIFS(Historico!$H$2:$H$471,Historico!$A$2:$A$471,$A7,Historico!$N$2:$N$471,"Sep-oct 2025")/SUMIFS(Historico!$G$2:$G$471,Historico!$A$2:$A$471,$A7,Historico!$N$2:$N$471,"Sep-oct 2025") -> 0.98453727
A8: OPL-Frio | B8: =SUMIFS(Historico!$F$2:$F$471,Historico!$A$2:$A$471,$A8,Historico!$N$2:$N$471,"Resto del año")/SUMIFS(Historico!$E$2:$E$471,Historico!$A$2:$A$471,$A8,Historico!$N$2:$N$471,"Resto del año") -> 1.0500323 | C8: =SUMIFS(Historico!$F$2:$F$471,Historico!$A$2:$A$471,$A8,Historico!$N$2:$N$471,"Temporada 2024-25")/SUMIFS(Historico!$E$2:$E$471,Historico!$A$2:$A$471,$A8,Historico!$N$2:$N$471,"Temporada 2024-25") -> 1.1398093 | D8: =SUMIFS(Historico!$F$2:$F$471,Historico!$A$2:$A$471,$A8,Historico!$N$2:$N$471,"Sep-oct 2025")/SUMIFS(Historico!$E$2:$E$471,Historico!$A$2:$A$471,$A8,Historico!$N$2:$N$471,"Sep-oct 2025") -> 1.1086431 | E8: =SUMIFS(Historico!$H$2:$H$471,Historico!$A$2:$A$471,$A8,Historico!$N$2:$N$471,"Resto del año")/SUMIFS(Historico!$G$2:$G$471,Historico!$A$2:$A$471,$A8,Historico!$N$2:$N$471,"Resto del año") -> 0.98593939 | F8: =SUMIFS(Historico!$H$2:$H$471,Historico!$A$2:$A$471,$A8,Historico!$N$2:$N$471,"Temporada 2024-25")/SUMIFS(Historico!$G$2:$G$471,Historico!$A$2:$A$471,$A8,Historico!$N$2:$N$471,"Temporada 2024-25") -> 0.98840698 | G8: =SUMIFS(Historico!$H$2:$H$471,Historico!$A$2:$A$471,$A8,Historico!$N$2:$N$471,"Sep-oct 2025")/SUMIFS(Historico!$G$2:$G$471,Historico!$A$2:$A$471,$A8,Historico!$N$2:$N$471,"Sep-oct 2025") -> 0.99383955
A10: Semáforo: verde 95–105 %, rojo > 105 %, café < 95 %.

Sheet Backtest
A1: Backtest a 11 semanas (resultado del notebook, sección 5)
A3: Centro | B3: Arranques | C3: MAE flujo (pp) | D3: Sesgo flujo (pp) | E3: MAE sin cambio (pp) | F3: MAE atajo 33 cajas (pp) | G3: Mejora vs. sin cambio
A4: CD-Norte | B4: 31 | C4: 2.46 | D4: 0.35 | E4: 5.8 | F4: 43.66 | G4: =1-C4/E4 -> 0.57586207
A5: CD-Centro | B5: 31 | C5: 2.64 | D5: -2.19 | E5: 5.1 | F5: 21.89 | G5: =1-C5/E5 -> 0.48235294
A6: CD-Oriente | B6: 31 | C6: 3.11 | D6: 2.59 | E6: 4.04 | F6: 55.32 | G6: =1-C6/E6 -> 0.23019802
A7: CD-Bebidas | B7: 31 | C7: 2.41 | D7: -0.61 | E7: 2.58 | F7: 23.87 | G7: =1-C7/E7 -> 0.065891473
A8: OPL-Frio | B8: 31 | C8: 1.48 | D8: 1.02 | E8: 3.29 | F8: 27.63 | G8: =1-C8/E8 -> 0.55015198
A10: Valores calculados en el notebook con calibración solo sobre semanas previas a cada arranque.
